Workbook

Sheet README
A1: LiDAR from the Ground Up — Worked Example Calculator
A2: Companion workbook to the 6-hour Mobile LiDAR Survey Seminar, D.S. Banks, PSM
A4: Every numbered worked example in the seminar book is rebuilt here with live Excel formulas, one sheet per module.
A5: How to use: change any blue input on a yellow cell and every result below it recalculates. Try your own sensor, range or speed.
A6: Columns: Value (the formula result) · Unit · Equation as printed in the book · Book value · Check (OK when the formula matches the book within the tolerance in column H) · US feet (lengths converted) · Notes.
A7: Colors: blue text = input you may edit; black = formula; green = formula that pulls from another example or sheet.
A8: Changing an input will (correctly) turn some Checks to CHECK, because the book values were computed for the original inputs.
A9: Example 14.5 uses the 'MC 20 m' sheet (2,000 random draws; press F9 to redraw). The 'Dataset' sheet holds the Module 21 sample project.
A10: Angles are entered in degrees and converted with RADIANS(). Excel's ATAN2 takes (x, y) — the reverse of most textbooks.
C12: Overall status
C13: Values that match the book (OK) | D13: =COUNTIF('M02 Math'!F:F,"OK")+COUNTIF('M03 Time of Flight'!F:F,"OK")+COUNTIF('M04 Beam'!F:F,"OK")+COUNTIF('M05 Polar'!F:F,"OK")+COUNTIF('M06 Rotation'!F:F,"OK")+COUNTIF('M07 IMU'!F:F,"OK")+COUNTIF('M08 Timing'!F:F,"OK")+COUNTIF('M09 Calibration'!F:F,"OK")+COUNTIF('M10 SLAM'!F:F,"OK")+COUNTIF('M11 Scan Matching'!F:F,"OK")+COUNTIF('M12 Factor Graphs'!F:F,"OK")+COUNTIF('M13 Accuracy'!F:F,"OK")+COUNTIF('M14 Error Budgets'!F:F,"OK")+COUNTIF('M15 Ouster OS0'!F:F,"OK")+COUNTIF('M16 GX5-GQ7'!F:F,"OK")+COUNTIF('M17 RIEGL'!F:F,"OK")+COUNTIF('M18 Processing'!F:F,"OK")+COUNTIF('M19 Florida'!F:F,"OK")+COUNTIF('M20 Practice'!F:F,"OK")+COUNTIF('M21 Capstone'!F:F,"OK")+COUNTIF(Dataset!F:F,"OK") -> 501
C14: Values that differ (CHECK) | D14: =COUNTIF('M02 Math'!F:F,"CHECK")+COUNTIF('M03 Time of Flight'!F:F,"CHECK")+COUNTIF('M04 Beam'!F:F,"CHECK")+COUNTIF('M05 Polar'!F:F,"CHECK")+COUNTIF('M06 Rotation'!F:F,"CHECK")+COUNTIF('M07 IMU'!F:F,"CHECK")+COUNTIF('M08 Timing'!F:F,"CHECK")+COUNTIF('M09 Calibration'!F:F,"CHECK")+COUNTIF('M10 SLAM'!F:F,"CHECK")+COUNTIF('M11 Scan Matching'!F:F,"CHECK")+COUNTIF('M12 Factor Graphs'!F:F,"CHECK")+COUNTIF('M13 Accuracy'!F:F,"CHECK")+COUNTIF('M14 Error Budgets'!F:F,"CHECK")+COUNTIF('M15 Ouster OS0'!F:F,"CHECK")+COUNTIF('M16 GX5-GQ7'!F:F,"CHECK")+COUNTIF('M17 RIEGL'!F:F,"CHECK")+COUNTIF('M18 Processing'!F:F,"CHECK")+COUNTIF('M19 Florida'!F:F,"CHECK")+COUNTIF('M20 Practice'!F:F,"CHECK")+COUNTIF('M21 Capstone'!F:F,"CHECK")+COUNTIF(Dataset!F:F,"CHECK") -> 0
C15: Worked examples in this workbook | D15: 86
A17: Example | B17: Sheet | C17: Title (click to go there) | D17: Values checked | E17: Status
A18: 2.1 | B18: M02 Math | C18: multiplying with powers of ten | D18: 1 | E18: =IF(COUNTIF('M02 Math'!F6:F10,"CHECK")>0,"CHECK",IF(COUNTIF('M02 Math'!F6:F10,"OK")>0,"OK","no book values")) -> OK
A19: 2.2 | B19: M02 Math | C19: a tiny angle at a long range | D19: 3 | E19: =IF(COUNTIF('M02 Math'!F12:F18,"CHECK")>0,"CHECK",IF(COUNTIF('M02 Math'!F12:F18,"OK")>0,"OK","no book values")) -> OK
A20: 2.3 | B20: M02 Math | C20: a 3-4-5 triangle | D20: 3 | E20: =IF(COUNTIF('M02 Math'!F20:F26,"CHECK")>0,"CHECK",IF(COUNTIF('M02 Math'!F20:F26,"OK")>0,"OK","no book values")) -> OK
A21: 2.4 | B21: M02 Math | C21: dot and cross products | D21: 7 | E21: =IF(COUNTIF('M02 Math'!F28:F42,"CHECK")>0,"CHECK",IF(COUNTIF('M02 Math'!F28:F42,"OK")>0,"OK","no book values")) -> OK
A22: 2.5 | B22: M02 Math | C22: matrix times vector | D22: 3 | E22: =IF(COUNTIF('M02 Math'!F44:F60,"CHECK")>0,"CHECK",IF(COUNTIF('M02 Math'!F44:F60,"OK")>0,"OK","no book values")) -> OK
A23: 2.6 | B23: M02 Math | C23: five elevation errors | D23: 5 | E23: =IF(COUNTIF('M02 Math'!F62:F73,"CHECK")>0,"CHECK",IF(COUNTIF('M02 Math'!F62:F73,"OK")>0,"OK","no book values")) -> OK
A24: 3.1 | B24: M03 Time of Flight | C24: range from a 400 ns echo | D24: 4 | E24: =IF(COUNTIF('M03 Time of Flight'!F6:F14,"CHECK")>0,"CHECK",IF(COUNTIF('M03 Time of Flight'!F6:F14,"OK")>0,"OK","no book values")) -> OK
A25: 3.2 | B25: M03 Time of Flight | C25: how fast can we fire? | D25: 3 | E25: =IF(COUNTIF('M03 Time of Flight'!F16:F22,"CHECK")>0,"CHECK",IF(COUNTIF('M03 Time of Flight'!F16:F22,"OK")>0,"OK","no book values")) -> OK
A26: 3.3 | B26: M03 Time of Flight | C26: phase measurement | D26: 6 | E26: =IF(COUNTIF('M03 Time of Flight'!F24:F35,"CHECK")>0,"CHECK",IF(COUNTIF('M03 Time of Flight'!F24:F35,"OK")>0,"OK","no book values")) -> OK
A27: 4.1 | B27: M04 Beam | C27: spot size at 50 m and 100 m | D27: 2 | E27: =IF(COUNTIF('M04 Beam'!F6:F13,"CHECK")>0,"CHECK",IF(COUNTIF('M04 Beam'!F6:F13,"OK")>0,"OK","no book values")) -> OK
A28: 4.2 | B28: M04 Beam | C28: comparing two targets | D28: 2 | E28: =IF(COUNTIF('M04 Beam'!F15:F24,"CHECK")>0,"CHECK",IF(COUNTIF('M04 Beam'!F15:F24,"OK")>0,"OK","no book values")) -> OK
A29: 4.3 | B29: M04 Beam | C29: how far can I see dark asphalt? | D29: 3 | E29: =IF(COUNTIF('M04 Beam'!F26:F35,"CHECK")>0,"CHECK",IF(COUNTIF('M04 Beam'!F26:F35,"OK")>0,"OK","no book values")) -> OK
A30: 5.1 | B30: M05 Polar | C30: one laser return to sensor coordinates | D30: 5 | E30: =IF(COUNTIF('M05 Polar'!F6:F15,"CHECK")>0,"CHECK",IF(COUNTIF('M05 Polar'!F6:F15,"OK")>0,"OK","no book values")) -> OK
A31: 5.2 | B31: M05 Polar | C31: planning a corridor survey | D31: 5 | E31: =IF(COUNTIF('M05 Polar'!F17:F29,"CHECK")>0,"CHECK",IF(COUNTIF('M05 Polar'!F17:F29,"OK")>0,"OK","no book values")) -> OK
A32: 6.1 | B32: M06 Rotation | C32: checking a frame with the cross product | D32: 3 | E32: =IF(COUNTIF('M06 Rotation'!F6:F17,"CHECK")>0,"CHECK",IF(COUNTIF('M06 Rotation'!F6:F17,"OK")>0,"OK","no book values")) -> OK
A33: 6.2 | B33: M06 Rotation | C33: rotate (3, 4) by 30° | D33: 3 | E33: =IF(COUNTIF('M06 Rotation'!F19:F25,"CHECK")>0,"CHECK",IF(COUNTIF('M06 Rotation'!F19:F25,"OK")>0,"OK","no book values")) -> OK
A34: 6.3 | B34: M06 Rotation | C34: one gyro step | D34: 5 | E34: =IF(COUNTIF('M06 Rotation'!F27:F36,"CHECK")>0,"CHECK",IF(COUNTIF('M06 Rotation'!F27:F36,"OK")>0,"OK","no book values")) -> OK
A35: 6.4 | B35: M06 Rotation | C35: 0.05° heading error at 80 m | D35: 4 | E35: =IF(COUNTIF('M06 Rotation'!F38:F44,"CHECK")>0,"CHECK",IF(COUNTIF('M06 Rotation'!F38:F44,"OK")>0,"OK","no book values")) -> OK
A36: 7.1 | B36: M07 IMU | C36: one strapdown step along a road | D36: 4 | E36: =IF(COUNTIF('M07 IMU'!F6:F17,"CHECK")>0,"CHECK",IF(COUNTIF('M07 IMU'!F6:F17,"OK")>0,"OK","no book values")) -> OK
A37: 7.2 | B37: M07 IMU | C37: tactical IMU coasting through a tunnel | D37: 7 | E37: =IF(COUNTIF('M07 IMU'!F19:F33,"CHECK")>0,"CHECK",IF(COUNTIF('M07 IMU'!F19:F33,"OK")>0,"OK","no book values")) -> OK
A38: 7.3 | B38: M07 IMU | C38: 0.1° tilt error | D38: 3 | E38: =IF(COUNTIF('M07 IMU'!F35:F41,"CHECK")>0,"CHECK",IF(COUNTIF('M07 IMU'!F35:F41,"OK")>0,"OK","no book values")) -> OK
A39: 7.4 | B39: M07 IMU | C39: preintegration in one dimension | D39: 6 | E39: =IF(COUNTIF('M07 IMU'!F43:F54,"CHECK")>0,"CHECK",IF(COUNTIF('M07 IMU'!F43:F54,"OK")>0,"OK","no book values")) -> OK
A40: 8.1 | B40: M08 Timing | C40: a 1 ms clock offset | D40: 3 | E40: =IF(COUNTIF('M08 Timing'!F6:F14,"CHECK")>0,"CHECK",IF(COUNTIF('M08 Timing'!F6:F14,"OK")>0,"OK","no book values")) -> OK
A41: 8.2 | B41: M08 Timing | C41: how big is the skew? | D41: 3 | E41: =IF(COUNTIF('M08 Timing'!F16:F23,"CHECK")>0,"CHECK",IF(COUNTIF('M08 Timing'!F16:F23,"OK")>0,"OK","no book values")) -> OK
A42: 9.1 | B42: M09 Calibration | C42: boresight residual at mapping range | D42: 2 | E42: =IF(COUNTIF('M09 Calibration'!F6:F11,"CHECK")>0,"CHECK",IF(COUNTIF('M09 Calibration'!F6:F11,"OK")>0,"OK","no book values")) -> OK
A43: 9.2 | B43: M09 Calibration | C43: direct georeferencing, every step | D43: 24 | E43: =IF(COUNTIF('M09 Calibration'!F13:F62,"CHECK")>0,"CHECK",IF(COUNTIF('M09 Calibration'!F13:F62,"OK")>0,"OK","no book values")) -> OK
...

Sheet M02 Math
A1: Module 2 — Math Toolkit: worked examples
A2: Blue = input (edit it) Black = formula Green = linked from another example/sheet Check = formula result vs. the value printed in the seminar book
A4: Step / quantity | B4: Value | C4: Unit | D4: Equation (as in the book) | E4: Book value | F4: Check vs. book | G4: US feet | H4: Tolerance | I4: Notes
A6: Worked example 2.1 — multiplying with powers of ten
A7: Given: c = 2.997×10⁸ m/s, t = 4.00×10⁻⁷ s. Find c×t.
A8: Speed c | B8: 299700000 | C8: m/s | D8: input | G8: =B8/0.3048 -> 9.8326772e+08
A9: Time t | B9: 4e-07 | C9: s | D9: input
A10: c × t | B10: =$B$8*$B$9 -> 119.88 | C10: m | D10: c·t = 2.997×4.00 × 10^(8−7) | E10: 119.88 | F10: =IF(ABS(B10-E10)<=H10,"OK","CHECK") -> OK | G10: =B10/0.3048 -> 393.30709 | H10: 0.005
A12: Worked example 2.2 — a tiny angle at a long range
A13: Given: Aiming error 20 arc-seconds at 100 m.
A14: Angle | B14: 20 | C14: arc-sec | D14: input
A15: Distance | B15: 100 | C15: m | D15: input | G15: =B15/0.3048 -> 328.08399
A16: Seconds to degrees | B16: =$B$14/3600 -> 0.0055555556 | C16: deg | D16: a/3600 | E16: 0.005556 | F16: =IF(ABS(B16-E16)<=H16,"OK","CHECK") -> OK | H16: 1e-06
A17: Degrees to radians | B17: =RADIANS($B$16) -> 9.6962736e-05 | C17: rad | D17: deg × π/180 | E17: 9.7e-05 | F17: =IF(ABS(B17-E17)<=H17,"OK","CHECK") -> OK | H17: 5e-07
A18: Arc length (sideways) | B18: =$B$15*$B$17 -> 0.0096962736 | C18: m | D18: s = d·θ (rad) | E18: 0.0097 | F18: =IF(ABS(B18-E18)<=H18,"OK","CHECK") -> OK | G18: =B18/0.3048 -> 0.031811921 | H18: 5e-05
A20: Worked example 2.3 — a 3-4-5 triangle
A21: Given: Slope distance 5.000 m at 36.87° above horizontal.
A22: Slope distance | B22: 5 | C22: m | D22: input | G22: =B22/0.3048 -> 16.404199
A23: Angle above horizontal | B23: 36.87 | C23: deg | D23: input
A24: Across | B24: =$B$22*COS(RADIANS($B$23)) -> 3.9999946 | C24: m | D24: L cos θ | E24: 4 | F24: =IF(ABS(B24-E24)<=H24,"OK","CHECK") -> OK | G24: =B24/0.3048 -> 13.123342 | H24: 0.0005
A25: Up | B25: =$B$22*SIN(RADIANS($B$23)) -> 3.0000071 | C25: m | D25: L sin θ | E25: 3 | F25: =IF(ABS(B25-E25)<=H25,"OK","CHECK") -> OK | G25: =B25/0.3048 -> 9.8425431 | H25: 0.0005
A26: Check: length | B26: =SQRT($B$24^2+$B$25^2) -> 5 | C26: m | D26: √(x²+z²) | E26: 5 | F26: =IF(ABS(B26-E26)<=H26,"OK","CHECK") -> OK | G26: =B26/0.3048 -> 16.404199 | H26: 0.0005
A28: Worked example 2.4 — dot and cross products
A29: Given: a = (1, 2, 0), b = (3, 0, 0).
A30: a1 | B30: 1 | D30: input
A31: a2 | B31: 2 | D31: input
A32: a3 | B32: 0 | D32: input
A33: b1 | B33: 3 | D33: input
A34: b2 | B34: 0 | D34: input
A35: b3 | B35: 0 | D35: input
A36: Dot product a·b | B36: =$B$30*$B$33+$B$31*$B$34+$B$32*$B$35 -> 3 | D36: a1b1+a2b2+a3b3 | E36: 3 | F36: =IF(ABS(B36-E36)<=H36,"OK","CHECK") -> OK | H36: 1e-09
A37: Cross x | B37: =$B$31*$B$35-$B$32*$B$34 -> 0 | D37: a2b3 − a3b2 | E37: 0 | F37: =IF(ABS(B37-E37)<=H37,"OK","CHECK") -> OK | H37: 1e-09
A38: Cross y | B38: =$B$32*$B$33-$B$30*$B$35 -> 0 | D38: a3b1 − a1b3 | E38: 0 | F38: =IF(ABS(B38-E38)<=H38,"OK","CHECK") -> OK | H38: 1e-09
A39: Cross z | B39: =$B$30*$B$34-$B$31*$B$33 -> -6 | D39: a1b2 − a2b1 | E39: -6 | F39: =IF(ABS(B39-E39)<=H39,"OK","CHECK") -> OK | H39: 1e-09
A40: Parallelogram area |a×b| | B40: =SQRT($B$37^2+$B$38^2+$B$39^2) -> 6 | D40: ‖a×b‖ | E40: 6 | F40: =IF(ABS(B40-E40)<=H40,"OK","CHECK") -> OK | H40: 1e-09
A41: Base |b| | B41: =SQRT($B$33^2+$B$34^2+$B$35^2) -> 3 | D41: ‖b‖ | E41: 3 | F41: =IF(ABS(B41-E41)<=H41,"OK","CHECK") -> OK | H41: 1e-09
A42: Point-to-line distance (height) | B42: =$B$40/$B$41 -> 2 | D42: ‖a×b‖/‖b‖ | E42: 2 | F42: =IF(ABS(B42-E42)<=H42,"OK","CHECK") -> OK | H42: 1e-09
A44: Worked example 2.5 — matrix times vector
A45: Given: M = [[2,0,1],[0,1,0],[1,0,3]], v = (1, 4, 2).
A46: M11 | B46: 2 | D46: input
...

Sheet M03 Time of Flight
A1: Module 3 — Time of Flight and Phase: worked examples
A2: Blue = input (edit it) Black = formula Green = linked from another example/sheet Check = formula result vs. the value printed in the seminar book
A4: Step / quantity | B4: Value | C4: Unit | D4: Equation (as in the book) | E4: Book value | F4: Check vs. book | G4: US feet | H4: Tolerance | I4: Notes
A6: Worked example 3.1 — range from a 400 ns echo
A7: Given: Δt = 400 ns; standard air n = 1.000300.
A8: Speed of light in vacuum | B8: 299792458 | C8: m/s | D8: input | G8: =B8/0.3048 -> 9.8357106e+08
A9: Refractive index of air | B9: 1.0003 | D9: input
A10: Round-trip time | B10: 400 | C10: ns | D10: input
A11: Speed of light in air | B11: =$B$8/$B$9 -> 2.9970255e+08 | C11: m/s | D11: c = c0/n | E11: 299702547 | F11: =IF(ABS(B11-E11)<=H11,"OK","CHECK") -> OK | G11: =B11/0.3048 -> 9.8327607e+08 | H11: 1
A12: Time in seconds | B12: =$B$10*0.000000001 -> 4e-07 | C12: s | D12: ns × 10⁻⁹ | E12: 4e-07 | F12: =IF(ABS(B12-E12)<=H12,"OK","CHECK") -> OK | H12: 1e-12
A13: Round-trip path | B13: =$B$11*$B$12 -> 119.88102 | C13: m | D13: c·Δt | E13: 119.881 | F13: =IF(ABS(B13-E13)<=H13,"OK","CHECK") -> OK | G13: =B13/0.3048 -> 393.31043 | H13: 0.0005
A14: Range | B14: =$B$13/2 -> 59.940509 | C14: m | D14: ρ = c·Δt/2 | E14: 59.941 | F14: =IF(ABS(B14-E14)<=H14,"OK","CHECK") -> OK | G14: =B14/0.3048 -> 196.65521 | H14: 0.0005
A16: Worked example 3.2 — how fast can we fire?
A17: Given: PRF = 1 MHz, c = 2.997×10⁸ m/s.
A18: Pulse repetition frequency | B18: 1000000 | C18: Hz | D18: input
A19: Speed of light | B19: 299700000 | C19: m/s | D19: input | G19: =B19/0.3048 -> 9.8326772e+08
A20: Time between pulses | B20: =1/$B$18 -> 1e-06 | C20: s | D20: 1/PRF | E20: 1e-06 | F20: =IF(ABS(B20-E20)<=H20,"OK","CHECK") -> OK | H20: 1e-12
A21: Maximum unambiguous range | B21: =$B$19/(2*$B$18) -> 149.85 | C21: m | D21: ρmax = c/(2·PRF) | E21: 149.9 | F21: =IF(ABS(B21-E21)<=H21,"OK","CHECK") -> OK | G21: =B21/0.3048 -> 491.63386 | H21: 0.051
A22: At double the rate (2 MHz) | B22: =$B$19/(2*2*$B$18) -> 74.925 | C22: m | D22: c/(2·2PRF) | E22: 74.9 | F22: =IF(ABS(B22-E22)<=H22,"OK","CHECK") -> OK | G22: =B22/0.3048 -> 245.81693 | H22: 0.05
A24: Worked example 3.3 — phase measurement
A25: Given: fm = 10 MHz, Δφ = 90°, c = 2.997×10⁸ m/s, N = 0.
A26: Modulation frequency | B26: 10000000 | C26: Hz | D26: input
A27: Phase difference | B27: 90 | C27: deg | D27: input
A28: Speed of light | B28: 299700000 | C28: m/s | D28: input | G28: =B28/0.3048 -> 9.8326772e+08
A29: Whole cycles N | B29: 0 | D29: input
A30: Modulation wavelength | B30: =$B$28/$B$26 -> 29.97 | C30: m | D30: λm = c/fm | E30: 29.97 | F30: =IF(ABS(B30-E30)<=H30,"OK","CHECK") -> OK | G30: =B30/0.3048 -> 98.326772 | H30: 0.005
A31: Half-wavelength | B31: =$B$30/2 -> 14.985 | C31: m | D31: λm/2 | E31: 14.985 | F31: =IF(ABS(B31-E31)<=H31,"OK","CHECK") -> OK | G31: =B31/0.3048 -> 49.163386 | H31: 0.0005
A32: Fraction of a cycle | B32: =$B$27/360 -> 0.25 | D32: Δφ/2π | E32: 0.25 | F32: =IF(ABS(B32-E32)<=H32,"OK","CHECK") -> OK | H32: 1e-09
A33: Range | B33: =$B$31*($B$29+$B$32) -> 3.74625 | C33: m | D33: ρ = (λm/2)(N + Δφ/2π) | E33: 3.746 | F33: =IF(ABS(B33-E33)<=H33,"OK","CHECK") -> OK | G33: =B33/0.3048 -> 12.290846 | H33: 0.0005
A34: Ambiguous alternative N+1 | B34: =$B$33+$B$31 -> 18.73125 | C34: m | D34: ρ + λm/2 | E34: 18.731 | F34: =IF(ABS(B34-E34)<=H34,"OK","CHECK") -> OK | G34: =B34/0.3048 -> 61.454232 | H34: 0.0005
A35: Ambiguous alternative N+2 | B35: =$B$33+2*$B$31 -> 33.71625 | C35: m | D35: ρ + 2·λm/2 | E35: 33.716 | F35: =IF(ABS(B35-E35)<=H35,"OK","CHECK") -> OK | G35: =B35/0.3048 -> 110.61762 | H35: 0.0005

Sheet M04 Beam
A1: Module 4 — Beam, Footprint and Reflectivity: worked examples
A2: Blue = input (edit it) Black = formula Green = linked from another example/sheet Check = formula result vs. the value printed in the seminar book
A4: Step / quantity | B4: Value | C4: Unit | D4: Equation (as in the book) | E4: Book value | F4: Check vs. book | G4: US feet | H4: Tolerance | I4: Notes
A6: Worked example 4.1 — spot size at 50 m and 100 m
A7: Given: d0 = 5 mm, γ = 0.3 mrad.
A8: Exit diameter | B8: 0.005 | C8: m | D8: input | G8: =B8/0.3048 -> 0.016404199
A9: Divergence | B9: 0.3 | C9: mrad | D9: input
A10: Range 1 | B10: 50 | C10: m | D10: input | G10: =B10/0.3048 -> 164.04199
A11: Range 2 | B11: 100 | C11: m | D11: input | G11: =B11/0.3048 -> 328.08399
A12: Footprint at range 1 | B12: =$B$8+$B$10*$B$9/1000 -> 0.02 | C12: m | D12: D = d0 + ρ·γ | E12: 0.02 | F12: =IF(ABS(B12-E12)<=H12,"OK","CHECK") -> OK | G12: =B12/0.3048 -> 0.065616798 | H12: 0.0005
A13: Footprint at range 2 | B13: =$B$8+$B$11*$B$9/1000 -> 0.035 | C13: m | D13: D = d0 + ρ·γ | E13: 0.035 | F13: =IF(ABS(B13-E13)<=H13,"OK","CHECK") -> OK | G13: =B13/0.3048 -> 0.1148294 | H13: 0.0005
A15: Worked example 4.2 — comparing two targets
A16: Given: A: white concrete 0.6 at 10 m head-on; B: asphalt 0.1 at 50 m, 60° incidence.
A17: Reflectivity A | B17: 0.6 | D17: input
A18: Range A | B18: 10 | C18: m | D18: input | G18: =B18/0.3048 -> 32.808399
A19: Incidence A | B19: 0 | C19: deg | D19: input
A20: Reflectivity B | B20: 0.1 | D20: input
A21: Range B | B21: 50 | C21: m | D21: input | G21: =B21/0.3048 -> 164.04199
A22: Incidence B | B22: 60 | C22: deg | D22: input
A23: Power ratio PB/PA | B23: =($B$20/$B$17)*(COS(RADIANS($B$22))/COS(RADIANS($B$19)))*($B$18^2/$B$21^2) -> 0.0033333333 | D23: (ρB/ρA)(cos θB/cos θA)(RA²/RB²) | E23: 0.00333 | F23: =IF(ABS(B23-E23)<=H23,"OK","CHECK") -> OK | H23: 5e-06
A24: A returns this many times more | B24: =1/$B$23 -> 300 | C24: × | D24: 1/ratio | E24: 300 | F24: =IF(ABS(B24-E24)<=H24,"OK","CHECK") -> OK | H24: 1
A26: Worked example 4.3 — how far can I see dark asphalt?
A27: Given: OS0 sees a 10% target to 35 m; max range ∝ √reflectivity.
A28: Range on 10% target | B28: 35 | C28: m | D28: input | G28: =B28/0.3048 -> 114.8294
A29: Reference reflectivity | B29: 10 | C29: % | D29: input
A30: Fresh asphalt reflectivity | B30: 5 | C30: % | D30: input
A31: Max range on fresh asphalt | B31: =$B$28*SQRT($B$30/$B$29) -> 24.748737 | C31: m | D31: R = R10·√(ρ/10%) | E31: 25 | F31: =IF(ABS(B31-E31)<=H31,"OK","CHECK") -> OK | G31: =B31/0.3048 -> 81.196645 | H31: 0.5
A32: Black car reflectivity | B32: 4 | C32: % | D32: input
A33: Max range on black car | B33: =$B$28*SQRT($B$32/$B$29) -> 22.135944 | C33: m | D33: R = R10·√(ρ/10%) | E33: 22 | F33: =IF(ABS(B33-E33)<=H33,"OK","CHECK") -> OK | G33: =B33/0.3048 -> 72.624487 | H33: 0.5
A34: Concrete reflectivity | B34: 40 | C34: % | D34: input
A35: Max range on concrete | B35: =$B$28*SQRT($B$34/$B$29) -> 70 | C35: m | D35: R = R10·√(ρ/10%) | E35: 70 | F35: =IF(ABS(B35-E35)<=H35,"OK","CHECK") -> OK | G35: =B35/0.3048 -> 229.65879 | H35: 0.5

Sheet M05 Polar
A1: Module 5 — Polar to Cartesian and Point Spacing: worked examples
A2: Blue = input (edit it) Black = formula Green = linked from another example/sheet Check = formula result vs. the value printed in the seminar book
A4: Step / quantity | B4: Value | C4: Unit | D4: Equation (as in the book) | E4: Book value | F4: Check vs. book | G4: US feet | H4: Tolerance | I4: Notes
A6: Worked example 5.1 — one laser return to sensor coordinates
A7: Given: ρ = 25.000 m, H = 40.0°, V = 15.0°; x forward, y left, z up.
A8: Range ρ | B8: 25 | C8: m | D8: input | G8: =B8/0.3048 -> 82.020997
A9: Horizontal angle H | B9: 40 | C9: deg | D9: input
A10: Vertical angle V | B10: 15 | C10: deg | D10: input
A11: Horizontal part ρ cos V | B11: =$B$8*COS(RADIANS($B$10)) -> 24.148146 | C11: m | D11: ρ cos V | E11: 24.148 | F11: =IF(ABS(B11-E11)<=H11,"OK","CHECK") -> OK | G11: =B11/0.3048 -> 79.2262 | H11: 0.0005
A12: x_s | B12: =$B$11*COS(RADIANS($B$9)) -> 18.498553 | C12: m | D12: ρ cos V cos H | E12: 18.499 | F12: =IF(ABS(B12-E12)<=H12,"OK","CHECK") -> OK | G12: =B12/0.3048 -> 60.69079 | H12: 0.0005
A13: y_s | B13: =$B$11*SIN(RADIANS($B$9)) -> 15.522129 | C13: m | D13: ρ cos V sin H | E13: 15.522 | F13: =IF(ABS(B13-E13)<=H13,"OK","CHECK") -> OK | G13: =B13/0.3048 -> 50.92562 | H13: 0.0005
A14: z_s | B14: =$B$8*SIN(RADIANS($B$10)) -> 6.4704761 | C14: m | D14: ρ sin V | E14: 6.47 | F14: =IF(ABS(B14-E14)<=H14,"OK","CHECK") -> OK | G14: =B14/0.3048 -> 21.228596 | H14: 0.0005
A15: Check: length | B15: =SQRT($B$12^2+$B$13^2+$B$14^2) -> 25 | C15: m | D15: √(x²+y²+z²) = ρ | E15: 25 | F15: =IF(ABS(B15-E15)<=H15,"OK","CHECK") -> OK | G15: =B15/0.3048 -> 82.020997 | H15: 0.0005
A17: Worked example 5.2 — planning a corridor survey
A18: Given: 16 channels, 0.2° step, 10 Hz, 15 m/s, target 20 m away.
A19: Channels | B19: 16 | D19: input
A20: Horizontal step | B20: 0.2 | C20: deg | D20: input
A21: Rotation rate | B21: 10 | C21: Hz | D21: input
A22: Speed | B22: 15 | C22: m/s | D22: input | G22: =B22/0.3048 -> 49.212598
A23: Range to target | B23: 20 | C23: m | D23: input | G23: =B23/0.3048 -> 65.616798
A24: Slower speed | B24: 5 | C24: m/s | D24: input | G24: =B24/0.3048 -> 16.404199
A25: Along-track spacing | B25: =$B$22/$B$21 -> 1.5 | C25: m | D25: Δalong = v/f | E25: 1.5 | F25: =IF(ABS(B25-E25)<=H25,"OK","CHECK") -> OK | G25: =B25/0.3048 -> 4.9212598 | H25: 0.0005
A26: Across-track spacing | B26: =$B$23*RADIANS($B$20) -> 0.06981317 | C26: m | D26: Δacross = ρ·Δθ | E26: 0.07 | F26: =IF(ABS(B26-E26)<=H26,"OK","CHECK") -> OK | G26: =B26/0.3048 -> 0.22904583 | H26: 0.0005
A27: Azimuth samples per rotation | B27: =360/$B$20 -> 1800 | D27: 360/Δθ | E27: 1800 | F27: =IF(ABS(B27-E27)<=H27,"OK","CHECK") -> OK | H27: 1e-06
A28: Point rate | B28: =$B$19*$B$27*$B$21 -> 288000 | C28: pts/s | D28: N = channels × Naz × f | E28: 288000 | F28: =IF(ABS(B28-E28)<=H28,"OK","CHECK") -> OK | H28: 1e-06
A29: Along-track spacing at slower speed | B29: =$B$24/$B$21 -> 0.5 | C29: m | D29: v2/f | E29: 0.5 | F29: =IF(ABS(B29-E29)<=H29,"OK","CHECK") -> OK | G29: =B29/0.3048 -> 1.6404199 | H29: 0.0005

Sheet M06 Rotation
A1: Module 6 — Pose, Right-Hand Rule and Rotations: worked examples
A2: Blue = input (edit it) Black = formula Green = linked from another example/sheet Check = formula result vs. the value printed in the seminar book
A4: Step / quantity | B4: Value | C4: Unit | D4: Equation (as in the book) | E4: Book value | F4: Check vs. book | G4: US feet | H4: Tolerance | I4: Notes
A6: Worked example 6.1 — checking a frame with the cross product
A7: Given: Datasheet: X forward, Y right, Z up. In FLU, forward=(1,0,0), right=(0,−1,0).
A8: Forward axis component 1 | B8: 1 | D8: input
A9: Forward axis component 2 | B9: 0 | D9: input
A10: Forward axis component 3 | B10: 0 | D10: input
A11: Right axis component 1 | B11: 0 | D11: input
A12: Right axis component 2 | B12: -1 | D12: input
A13: Right axis component 3 | B13: 0 | D13: input
A14: X × Y, x | B14: =$B$9*$B$13-$B$10*$B$12 -> 0 | D14: cross product | E14: 0 | F14: =IF(ABS(B14-E14)<=H14,"OK","CHECK") -> OK | H14: 1e-09
A15: X × Y, y | B15: =$B$10*$B$11-$B$8*$B$13 -> 0 | D15: cross product | E15: 0 | F15: =IF(ABS(B15-E15)<=H15,"OK","CHECK") -> OK | H15: 1e-09
A16: X × Y, z (thumb) | B16: =$B$8*$B$12-$B$9*$B$11 -> -1 | D16: −1 = thumb points down | E16: -1 | F16: =IF(ABS(B16-E16)<=H16,"OK","CHECK") -> OK | H16: 1e-09
A17: Result: Z = X × Y points DOWN, so 'X forward, Y right, Z up' is left-handed. Confirm FRD with the manufacturer.
A19: Worked example 6.2 — rotate (3, 4) by 30°
A20: x | B20: 3 | D20: input
A21: y | B21: 4 | D21: input
A22: Rotation angle | B22: 30 | C22: deg | D22: input
A23: x′ | B23: =COS(RADIANS($B$22))*$B$20-SIN(RADIANS($B$22))*$B$21 -> 0.59807621 | D23: x cos α − y sin α | E23: 0.598 | F23: =IF(ABS(B23-E23)<=H23,"OK","CHECK") -> OK | H23: 0.0005
A24: y′ | B24: =SIN(RADIANS($B$22))*$B$20+COS(RADIANS($B$22))*$B$21 -> 4.9641016 | D24: x sin α + y cos α | E24: 4.964 | F24: =IF(ABS(B24-E24)<=H24,"OK","CHECK") -> OK | H24: 0.0005
A25: Length after (check) | B25: =SQRT($B$23^2+$B$24^2) -> 5 | D25: unchanged = 5 | E25: 5 | F25: =IF(ABS(B25-E25)<=H25,"OK","CHECK") -> OK | H25: 0.0005
A27: Worked example 6.3 — one gyro step
A28: Given: ωz = 0.0842 rad/s, Δt = 0.005 s (200 Hz), start heading 0.
A29: Yaw rate ωz | B29: 0.0842 | C29: rad/s | D29: input
A30: Time step | B30: 0.005 | C30: s | D30: input
A31: Steps (1 s) | B31: 200 | D31: input
A32: Rotation in one step | B32: =$B$29*$B$30 -> 0.000421 | C32: rad | D32: α = ω·Δt | E32: 0.000421 | F32: =IF(ABS(B32-E32)<=H32,"OK","CHECK") -> OK | H32: 5e-07
A33: In degrees | B33: =DEGREES($B$32) -> 0.024121523 | C33: deg | E33: 0.0241 | F33: =IF(ABS(B33-E33)<=H33,"OK","CHECK") -> OK | H33: 5e-05
A34: cos α | B34: =COS($B$32) -> 0.99999991 | E34: 0.99999991 | F34: =IF(ABS(B34-E34)<=H34,"OK","CHECK") -> OK | H34: 1e-08
A35: Heading after 200 steps | B35: =$B$31*$B$32 -> 0.0842 | C35: rad | D35: Σα | E35: 0.0842 | F35: =IF(ABS(B35-E35)<=H35,"OK","CHECK") -> OK | H35: 1e-06
A36: In degrees | B36: =DEGREES($B$35) -> 4.8243046 | C36: deg | E36: 4.82 | F36: =IF(ABS(B36-E36)<=H36,"OK","CHECK") -> OK | H36: 0.005
A38: Worked example 6.4 — 0.05° heading error at 80 m
A39: Heading error | B39: 0.05 | C39: deg | D39: input
A40: Range | B40: 80 | C40: m | D40: input | G40: =B40/0.3048 -> 262.46719
A41: Radians | B41: =RADIANS($B$39) -> 0.00087266463 | C41: rad | D41: deg × π/180 | E41: 0.0008727 | F41: =IF(ABS(B41-E41)<=H41,"OK","CHECK") -> OK | H41: 1e-07
A42: Sideways displacement | B42: =$B$40*$B$41 -> 0.06981317 | C42: m | D42: δ = ρ·δα | E42: 0.0698 | F42: =IF(ABS(B42-E42)<=H42,"OK","CHECK") -> OK | G42: =B42/0.3048 -> 0.22904583 | H42: 5e-05
A43: Same error at 100 m | B43: =100*$B$41*100 -> 8.7266463 | C43: cm | D43: 100 m × δα | E43: 8.7 | F43: =IF(ABS(B43-E43)<=H43,"OK","CHECK") -> OK | G43: =B43/30.48 -> 0.28630729 | H43: 0.05
A44: 0.1° at 100 m | B44: =100*RADIANS(0.1)*100 -> 17.453293 | C44: cm | D44: 100 m × 0.1° | E44: 17.5 | F44: =IF(ABS(B44-E44)<=H44,"OK","CHECK") -> OK | G44: =B44/30.48 -> 0.57261458 | H44: 0.06

Sheet M07 IMU
A1: Module 7 — IMU and Strapdown Navigation: worked examples
A2: Blue = input (edit it) Black = formula Green = linked from another example/sheet Check = formula result vs. the value printed in the seminar book
A4: Step / quantity | B4: Value | C4: Unit | D4: Equation (as in the book) | E4: Book value | F4: Check vs. book | G4: US feet | H4: Tolerance | I4: Notes
A6: Worked example 7.1 — one strapdown step along a road
A7: Given: 100 Hz; level; v = 15.000 m/s; x = 100.000 m; âx = 0.80, âz = 9.81 m/s².
A8: Time step | B8: 0.01 | C8: s | D8: input
A9: Velocity | B9: 15 | C9: m/s | D9: input | G9: =B9/0.3048 -> 49.212598
A10: Position | B10: 100 | C10: m | D10: input | G10: =B10/0.3048 -> 328.08399
A11: Accelerometer x | B11: 0.8 | C11: m/s² | D11: input
A12: Accelerometer z | B12: 9.81 | C12: m/s² | D12: input
A13: Gravity | B13: 9.81 | C13: m/s² | D13: input
A14: Vertical velocity change | B14: =(-$B$13+$B$12)*$B$8 -> 0 | C14: m/s | D14: (g + âz)Δt, g = −9.81 | E14: 0 | F14: =IF(ABS(B14-E14)<=H14,"OK","CHECK") -> OK | G14: =B14/0.3048 -> 0 | H14: 1e-09
A15: New forward velocity | B15: =$B$9+$B$11*$B$8 -> 15.008 | C15: m/s | D15: v + âΔt | E15: 15.008 | F15: =IF(ABS(B15-E15)<=H15,"OK","CHECK") -> OK | G15: =B15/0.3048 -> 49.238845 | H15: 0.0005
A16: New forward position | B16: =$B$10+$B$9*$B$8+0.5*$B$11*$B$8^2 -> 100.15004 | C16: m | D16: x + vΔt + ½âΔt² | E16: 100.15004 | F16: =IF(ABS(B16-E16)<=H16,"OK","CHECK") -> OK | G16: =B16/0.3048 -> 328.57625 | H16: 5e-06
A17: Speed-up | B17: =$B$11*$B$8*1000 -> 8 | C17: mm/s | D17: âΔt | E17: 8 | F17: =IF(ABS(B17-E17)<=H17,"OK","CHECK") -> OK | H17: 1e-06
A19: Worked example 7.2 — tactical IMU coasting through a tunnel
A20: Given: Gyro bias 1°/h, accel bias 0.5 mg, 15 m/s, 60 s unaided.
A21: Gyro bias | B21: 1 | C21: deg/h | D21: input
A22: Accel bias | B22: 0.5 | C22: mg | D22: input
A23: Speed | B23: 15 | C23: m/s | D23: input | G23: =B23/0.3048 -> 49.212598
A24: Outage | B24: 60 | C24: s | D24: input
A25: Standard gravity | B25: 9.80665 | C25: m/s² | D25: input
A26: Shorter outage | B26: 30 | C26: s | D26: input
A27: Gyro bias in rad/s | B27: =RADIANS($B$21/3600) -> 4.8481368e-06 | C27: rad/s | D27: (1/3600)°/s × π/180 | E27: 4.848e-06 | F27: =IF(ABS(B27-E27)<=H27,"OK","CHECK") -> OK | H27: 1e-09
A28: Heading error | B28: =$B$27*$B$24 -> 0.00029088821 | C28: rad | D28: bg·t | E28: 0.0002909 | F28: =IF(ABS(B28-E28)<=H28,"OK","CHECK") -> OK | H28: 1e-07
A29: Heading error (deg) | B29: =DEGREES($B$28) -> 0.016666667 | C29: deg | E29: 0.0167 | F29: =IF(ABS(B29-E29)<=H29,"OK","CHECK") -> OK | H29: 5e-05
A30: Sideways error | B30: =0.5*$B$23*$B$27*$B$24^2 -> 0.13089969 | C30: m | D30: ½·v·bg·t² | E30: 0.131 | F30: =IF(ABS(B30-E30)<=H30,"OK","CHECK") -> OK | G30: =B30/0.3048 -> 0.42946094 | H30: 0.0005
A31: Accel bias in m/s² | B31: =$B$22*0.001*$B$25 -> 0.004903325 | C31: m/s² | D31: mg × 10⁻³ × g | E31: 0.004903 | F31: =IF(ABS(B31-E31)<=H31,"OK","CHECK") -> OK | H31: 1e-06
A32: Along-track error | B32: =0.5*$B$31*$B$24^2 -> 8.825985 | C32: m | D32: ½·ba·t² | E32: 8.83 | F32: =IF(ABS(B32-E32)<=H32,"OK","CHECK") -> OK | G32: =B32/0.3048 -> 28.956644 | H32: 0.005
A33: Along-track error after 30 s | B33: =0.5*$B$31*$B$26^2 -> 2.2064962 | C33: m | D33: ½·ba·t² | E33: 2.2 | F33: =IF(ABS(B33-E33)<=H33,"OK","CHECK") -> OK | G33: =B33/0.3048 -> 7.2391609 | H33: 0.05
A35: Worked example 7.3 — 0.1° tilt error
A36: Tilt error | B36: 0.1 | C36: deg | D36: input
A37: Gravity | B37: 9.80665 | C37: m/s² | D37: input
A38: Time | B38: 10 | C38: s | D38: input
A39: Leaked acceleration | B39: =$B$37*SIN(RADIANS($B$36)) -> 0.017115824 | C39: m/s² | D39: g sin δθ | E39: 0.01712 | F39: =IF(ABS(B39-E39)<=H39,"OK","CHECK") -> OK | H39: 1e-05
A40: In mg | B40: =$B$39/$B$37*1000 -> 1.7453284 | C40: mg | E40: 1.7 | F40: =IF(ABS(B40-E40)<=H40,"OK","CHECK") -> OK | H40: 0.05
A41: Position error after t | B41: =0.5*$B$39*$B$38^2 -> 0.85579122 | C41: m | D41: ½·a·t² | E41: 0.86 | F41: =IF(ABS(B41-E41)<=H41,"OK","CHECK") -> OK | G41: =B41/0.3048 -> 2.807714 | H41: 0.005
A43: Worked example 7.4 — preintegration in one dimension
A44: Given: 10 IMU samples at 100 Hz, â = 0.50 m/s², vi = 12.000 m/s.
A45: Samples | B45: 10 | D45: input
...

Sheet M08 Timing
A1: Module 8 — Timing and De-skew: worked examples
A2: Blue = input (edit it) Black = formula Green = linked from another example/sheet Check = formula result vs. the value printed in the seminar book
A4: Step / quantity | B4: Value | C4: Unit | D4: Equation (as in the book) | E4: Book value | F4: Check vs. book | G4: US feet | H4: Tolerance | I4: Notes
A6: Worked example 8.1 — a 1 ms clock offset
A7: Given: δt = 1 ms; 20 m/s; turning 30°/s; point 50 m away.
A8: Clock offset | B8: 0.001 | C8: s | D8: input
A9: Speed | B9: 20 | C9: m/s | D9: input | G9: =B9/0.3048 -> 65.616798
A10: Turn rate | B10: 30 | C10: deg/s | D10: input
A11: Range | B11: 50 | C11: m | D11: input | G11: =B11/0.3048 -> 164.04199
A12: Along-track error | B12: =$B$9*$B$8 -> 0.02 | C12: m | D12: v·δt | E12: 0.02 | F12: =IF(ABS(B12-E12)<=H12,"OK","CHECK") -> OK | G12: =B12/0.3048 -> 0.065616798 | H12: 0.0005
A13: Rotation during offset | B13: =RADIANS($B$10*$B$8) -> 0.00052359878 | C13: rad | D13: ω·δt | E13: 0.000524 | F13: =IF(ABS(B13-E13)<=H13,"OK","CHECK") -> OK | H13: 5e-07
A14: Sideways error at range | B14: =$B$11*$B$13 -> 0.026179939 | C14: m | D14: ρ·ω·δt | E14: 0.026 | F14: =IF(ABS(B14-E14)<=H14,"OK","CHECK") -> OK | G14: =B14/0.3048 -> 0.085892188 | H14: 0.0005
A16: Worked example 8.2 — how big is the skew?
A17: Given: 10 Hz sweep, 15 m/s, point fired 0.075 s into the sweep.
A18: Sweep rate | B18: 10 | C18: Hz | D18: input
A19: Speed | B19: 15 | C19: m/s | D19: input | G19: =B19/0.3048 -> 49.212598
A20: Time into sweep | B20: 0.075 | C20: s | D20: input
A21: Sweep period | B21: =1/$B$18 -> 0.1 | C21: s | D21: 1/f | E21: 0.1 | F21: =IF(ABS(B21-E21)<=H21,"OK","CHECK") -> OK | H21: 1e-09
A22: Distance moved by this point | B22: =$B$19*$B$20 -> 1.125 | C22: m | D22: v·τ | E22: 1.125 | F22: =IF(ABS(B22-E22)<=H22,"OK","CHECK") -> OK | G22: =B22/0.3048 -> 3.6909449 | H22: 0.0005
A23: First-to-last difference | B23: =$B$19*$B$21 -> 1.5 | C23: m | D23: v·T | E23: 1.5 | F23: =IF(ABS(B23-E23)<=H23,"OK","CHECK") -> OK | G23: =B23/0.3048 -> 4.9212598 | H23: 0.0005

Sheet M09 Calibration
A1: Module 9 — Lever Arm, Boresight and Direct Georeferencing: worked examples
A2: Blue = input (edit it) Black = formula Green = linked from another example/sheet Check = formula result vs. the value printed in the seminar book
A4: Step / quantity | B4: Value | C4: Unit | D4: Equation (as in the book) | E4: Book value | F4: Check vs. book | G4: US feet | H4: Tolerance | I4: Notes
A6: Worked example 9.1 — boresight residual at mapping range
A7: Given: Residual boresight 0.05°; target 80 m away.
A8: Boresight residual | B8: 0.05 | C8: deg | D8: input
A9: Range | B9: 80 | C9: m | D9: input | G9: =B9/0.3048 -> 262.46719
A10: Radians | B10: =RADIANS($B$8) -> 0.00087266463 | C10: rad | E10: 0.0008727 | F10: =IF(ABS(B10-E10)<=H10,"OK","CHECK") -> OK | H10: 1e-07
A11: Displacement | B11: =$B$9*$B$10 -> 0.06981317 | C11: m | D11: ρ·δα | E11: 0.0698 | F11: =IF(ABS(B11-E11)<=H11,"OK","CHECK") -> OK | G11: =B11/0.3048 -> 0.22904583 | H11: 5e-05
A13: Worked example 9.2 — direct georeferencing, every step
A14: Given: FLU body, ENU world, ZYX angles. pW = (1000, 2000, 10) m; roll 1.0°, pitch −0.5°, yaw 30.0°; lever arm (0.120, 0, 0.085) m; boresight (0.05°, −0.03°, 0.02°); ρ = 25.000 m, H = 10.0°, V = 2.0°. The workbook uses exact rotation matrices; the book used the small-angle form for boresight.
A15: IMU position E | B15: 1000 | C15: m | D15: input | G15: =B15/0.3048 -> 3280.8399
A16: IMU position N | B16: 2000 | C16: m | D16: input | G16: =B16/0.3048 -> 6561.6798
A17: IMU position U | B17: 10 | C17: m | D17: input | G17: =B17/0.3048 -> 32.808399
A18: Roll | B18: 1 | C18: deg | D18: input
A19: Pitch | B19: -0.5 | C19: deg | D19: input
A20: Yaw | B20: 30 | C20: deg | D20: input
A21: Lever arm x | B21: 0.12 | C21: m | D21: input | G21: =B21/0.3048 -> 0.39370079
A22: Lever arm y | B22: 0 | C22: m | D22: input | G22: =B22/0.3048 -> 0
A23: Lever arm z | B23: 0.085 | C23: m | D23: input | G23: =B23/0.3048 -> 0.27887139
A24: Boresight roll | B24: 0.05 | C24: deg | D24: input
A25: Boresight pitch | B25: -0.03 | C25: deg | D25: input
A26: Boresight yaw | B26: 0.02 | C26: deg | D26: input
A27: Range | B27: 25 | C27: m | D27: input | G27: =B27/0.3048 -> 82.020997
A28: Horizontal angle | B28: 10 | C28: deg | D28: input
A29: Vertical angle | B29: 2 | C29: deg | D29: input
A30: Step 1: x_S | B30: =$B$27*COS(RADIANS($B$29))*COS(RADIANS($B$28)) -> 24.605196 | C30: m | D30: ρ cos V cos H | E30: 24.6052 | F30: =IF(ABS(B30-E30)<=H30,"OK","CHECK") -> OK | G30: =B30/0.3048 -> 80.725708 | H30: 5e-05
A31: Step 1: y_S | B31: =$B$27*COS(RADIANS($B$29))*SIN(RADIANS($B$28)) -> 4.3385599 | C31: m | D31: ρ cos V sin H | E31: 4.3386 | F31: =IF(ABS(B31-E31)<=H31,"OK","CHECK") -> OK | G31: =B31/0.3048 -> 14.23412 | H31: 5e-05
A32: Step 1: z_S | B32: =$B$27*SIN(RADIANS($B$29)) -> 0.87248742 | C32: m | D32: ρ sin V | E32: 0.8725 | F32: =IF(ABS(B32-E32)<=H32,"OK","CHECK") -> OK | G32: =B32/0.3048 -> 2.8624915 | H32: 5e-05
A33: Step 2: boresight R11 | B33: =COS(RADIANS($B$26))*COS(RADIANS($B$25)) -> 0.9999998 | D33: Rz(δψ)Ry(δθ)Rx(δφ)
A34: Step 2: boresight R12 | B34: =COS(RADIANS($B$26))*SIN(RADIANS($B$25))*SIN(RADIANS($B$24))-SIN(RADIANS($B$26))*COS(RADIANS($B$24)) -> -0.00034952264 | D34: Rz(δψ)Ry(δθ)Rx(δφ)
A35: Step 2: boresight R13 | B35: =COS(RADIANS($B$26))*SIN(RADIANS($B$25))*COS(RADIANS($B$24))+SIN(RADIANS($B$26))*SIN(RADIANS($B$24)) -> -0.0005232939 | D35: Rz(δψ)Ry(δθ)Rx(δφ)
A36: Step 2: boresight R21 | B36: =SIN(RADIANS($B$26))*COS(RADIANS($B$25)) -> 0.0003490658 | D36: Rz(δψ)Ry(δθ)Rx(δφ)
A37: Step 2: boresight R22 | B37: =SIN(RADIANS($B$26))*SIN(RADIANS($B$25))*SIN(RADIANS($B$24))+COS(RADIANS($B$26))*COS(RADIANS($B$24)) -> 0.99999956 | D37: Rz(δψ)Ry(δθ)Rx(δφ)
A38: Step 2: boresight R23 | B38: =SIN(RADIANS($B$26))*SIN(RADIANS($B$25))*COS(RADIANS($B$24))-COS(RADIANS($B$26))*SIN(RADIANS($B$24)) -> -0.00087284723 | D38: Rz(δψ)Ry(δθ)Rx(δφ)
A39: Step 2: boresight R31 | B39: =-SIN(RADIANS($B$25)) -> 0.00052359875 | D39: Rz(δψ)Ry(δθ)Rx(δφ)
A40: Step 2: boresight R32 | B40: =COS(RADIANS($B$25))*SIN(RADIANS($B$24)) -> 0.0008726644 | D40: Rz(δψ)Ry(δθ)Rx(δφ)
A41: Step 2: boresight R33 | B41: =COS(RADIANS($B$25))*COS(RADIANS($B$24)) -> 0.99999948 | D41: Rz(δψ)Ry(δθ)Rx(δφ)
A42: Step 2: rotated point, axis 1 | B42: =$B$33*$B$30+$B$34*$B$31+$B$35*$B$32 -> 24.603218 | C42: m | D42: R^B_S · x_S | E42: 24.6032 | F42: =IF(ABS(B42-E42)<=H42,"OK","CHECK") -> OK | G42: =B42/0.3048 -> 80.719219 | H42: 0.0002
A43: Step 2: rotated point, axis 2 | B43: =$B$36*$B$30+$B$37*$B$31+$B$38*$B$32 -> 4.3463853 | C43: m | D43: R^B_S · x_S | E43: 4.3464 | F43: =IF(ABS(B43-E43)<=H43,"OK","CHECK") -> OK | G43: =B43/0.3048 -> 14.259794 | H43: 0.0002
...

Sheet M10 SLAM
A1: Module 10 — SLAM, Motion Models and the Kalman Filter: worked examples
A2: Blue = input (edit it) Black = formula Green = linked from another example/sheet Check = formula result vs. the value printed in the seminar book
A4: Step / quantity | B4: Value | C4: Unit | D4: Equation (as in the book) | E4: Book value | F4: Check vs. book | G4: US feet | H4: Tolerance | I4: Notes
A6: Worked example 10.1 — predicting the next pose
A7: Given: Pose (10.00, 5.00, 0°); wheel distances L = 0.40 m, R = 0.45 m; track w = 0.30 m.
A8: x | B8: 10 | C8: m | D8: input | G8: =B8/0.3048 -> 32.808399
A9: y | B9: 5 | C9: m | D9: input | G9: =B9/0.3048 -> 16.404199
A10: Heading θ | B10: 0 | C10: deg | D10: input
A11: Left wheel distance | B11: 0.4 | C11: m | D11: input | G11: =B11/0.3048 -> 1.312336
A12: Right wheel distance | B12: 0.45 | C12: m | D12: input | G12: =B12/0.3048 -> 1.476378
A13: Track width | B13: 0.3 | C13: m | D13: input | G13: =B13/0.3048 -> 0.98425197
A14: Turn angle α | B14: =($B$12-$B$11)/$B$13 -> 0.16666667 | C14: rad | D14: α = (R − L)/w | E14: 0.16667 | F14: =IF(ABS(B14-E14)<=H14,"OK","CHECK") -> OK | H14: 5e-06
A15: Turn angle (deg) | B15: =DEGREES($B$14) -> 9.5492966 | C15: deg | E15: 9.549 | F15: =IF(ABS(B15-E15)<=H15,"OK","CHECK") -> OK | H15: 0.0005
A16: Inner radius | B16: =$B$11/$B$14 -> 2.4 | C16: m | D16: r = L/α | E16: 2.4 | F16: =IF(ABS(B16-E16)<=H16,"OK","CHECK") -> OK | G16: =B16/0.3048 -> 7.8740157 | H16: 0.0005
A17: Center radius | B17: =$B$16+$B$13/2 -> 2.55 | C17: m | D17: r + w/2 | E17: 2.55 | F17: =IF(ABS(B17-E17)<=H17,"OK","CHECK") -> OK | G17: =B17/0.3048 -> 8.3661417 | H17: 0.0005
A18: x′ | B18: =$B$8+$B$17*(SIN(RADIANS($B$10)+$B$14)-SIN(RADIANS($B$10))) -> 10.423035 | C18: m | D18: x + rc(sin(θ+α) − sin θ) | E18: 10.423 | F18: =IF(ABS(B18-E18)<=H18,"OK","CHECK") -> OK | G18: =B18/0.3048 -> 34.19631 | H18: 0.0005
A19: y′ | B19: =$B$9-$B$17*(COS(RADIANS($B$10)+$B$14)-COS(RADIANS($B$10))) -> 5.0353348 | C19: m | D19: y − rc(cos(θ+α) − cos θ) | E19: 5.0353 | F19: =IF(ABS(B19-E19)<=H19,"OK","CHECK") -> OK | G19: =B19/0.3048 -> 16.520127 | H19: 6e-05
A20: θ′ | B20: =$B$10+$B$15 -> 9.5492966 | C20: deg | D20: θ + α | E20: 9.549 | F20: =IF(ABS(B20-E20)<=H20,"OK","CHECK") -> OK | H20: 0.0005
A22: Worked example 10.2 — 1-D Kalman update
A23: Given: Prediction 100.0 ± 0.50 m; measurement 100.4 ± 0.20 m.
A24: Predicted value | B24: 100 | C24: m | D24: input | G24: =B24/0.3048 -> 328.08399
A25: Predicted σ | B25: 0.5 | C25: m | D25: input | G25: =B25/0.3048 -> 1.6404199
A26: Measurement | B26: 100.4 | C26: m | D26: input | G26: =B26/0.3048 -> 329.39633
A27: Measurement σ | B27: 0.2 | C27: m | D27: input | G27: =B27/0.3048 -> 0.65616798
A28: Prediction variance | B28: =$B$25^2 -> 0.25 | C28: m² | D28: σ̄² | E28: 0.25 | F28: =IF(ABS(B28-E28)<=H28,"OK","CHECK") -> OK | G28: =B28/0.09290304 -> 2.6909776 | H28: 1e-09
A29: Measurement variance | B29: =$B$27^2 -> 0.04 | C29: m² | D29: σz² | E29: 0.04 | F29: =IF(ABS(B29-E29)<=H29,"OK","CHECK") -> OK | G29: =B29/0.09290304 -> 0.43055642 | H29: 1e-09
A30: Gain K | B30: =$B$28/($B$28+$B$29) -> 0.86206897 | D30: K = σ̄²/(σ̄² + σz²) | E30: 0.8621 | F30: =IF(ABS(B30-E30)<=H30,"OK","CHECK") -> OK | H30: 5e-05
A31: Updated value | B31: =$B$24+$B$30*($B$26-$B$24) -> 100.34483 | C31: m | D31: μ = μ̄ + K(z − μ̄) | E31: 100.345 | F31: =IF(ABS(B31-E31)<=H31,"OK","CHECK") -> OK | G31: =B31/0.3048 -> 329.21531 | H31: 0.0005
A32: Updated variance | B32: =(1-$B$30)*$B$28 -> 0.034482759 | C32: m² | D32: (1 − K)σ̄² | E32: 0.03448 | F32: =IF(ABS(B32-E32)<=H32,"OK","CHECK") -> OK | G32: =B32/0.09290304 -> 0.37116932 | H32: 5e-06
A33: Updated σ | B33: =SQRT($B$32) -> 0.18569534 | C33: m | E33: 0.186 | F33: =IF(ABS(B33-E33)<=H33,"OK","CHECK") -> OK | G33: =B33/0.3048 -> 0.60923667 | H33: 0.0005
A35: Worked example 10.3 — EKF prediction for our motion
A36: Given: Motion of Example 10.1; P = diag(0.01, 0.01, 0.001); Q = diag(0.002, 0.002, 0.0005).
A37: P11 | B37: 0.01 | D37: input
A38: P22 | B38: 0.01 | D38: input
A39: P33 | B39: 0.001 | D39: input
A40: Q11 | B40: 0.002 | D40: input
A41: Q22 | B41: 0.002 | D41: input
A42: Q33 | B42: 0.0005 | D42: input
A43: Jacobian G13 = ∂x′/∂θ | B43: =$B$17*(COS(RADIANS($B$10)+$B$14)-COS(RADIANS($B$10))) -> -0.03533476 | D43: rc(cos(θ+α) − cos θ) | E43: -0.0353 | F43: =IF(ABS(B43-E43)<=H43,"OK","CHECK") -> OK | H43: 5e-05
A44: Jacobian G23 = ∂y′/∂θ | B44: =$B$17*(SIN(RADIANS($B$10)+$B$14)-SIN(RADIANS($B$10))) -> 0.42303514 | D44: rc(sin(θ+α) − sin θ) | E44: 0.423 | F44: =IF(ABS(B44-E44)<=H44,"OK","CHECK") -> OK | H44: 5e-05
...

Sheet M11 Scan Matching
A1: Module 11 — Scan Matching (ICP and LOAM features): worked examples
A2: Blue = input (edit it) Black = formula Green = linked from another example/sheet Check = formula result vs. the value printed in the seminar book
A4: Step / quantity | B4: Value | C4: Unit | D4: Equation (as in the book) | E4: Book value | F4: Check vs. book | G4: US feet | H4: Tolerance | I4: Notes
A6: Worked example 11.1 — best fit of four matched points (with continuation)
A7: Given: Source p = (0,0),(2,0),(2,1),(0,3); target q = (1.000,0.500),(2.970,0.847),(2.796,1.832),(0.479,3.454).
A8: p1 x | B8: 0 | C8: m | D8: input | G8: =B8/0.3048 -> 0
A9: p2 x | B9: 2 | C9: m | D9: input | G9: =B9/0.3048 -> 6.5616798
A10: p3 x | B10: 2 | C10: m | D10: input | G10: =B10/0.3048 -> 6.5616798
A11: p4 x | B11: 0 | C11: m | D11: input | G11: =B11/0.3048 -> 0
A12: p1 y | B12: 0 | C12: m | D12: input | G12: =B12/0.3048 -> 0
A13: p2 y | B13: 0 | C13: m | D13: input | G13: =B13/0.3048 -> 0
A14: p3 y | B14: 1 | C14: m | D14: input | G14: =B14/0.3048 -> 3.2808399
A15: p4 y | B15: 3 | C15: m | D15: input | G15: =B15/0.3048 -> 9.8425197
A16: q1 x | B16: 1 | C16: m | D16: input | G16: =B16/0.3048 -> 3.2808399
A17: q2 x | B17: 2.97 | C17: m | D17: input | G17: =B17/0.3048 -> 9.7440945
A18: q3 x | B18: 2.796 | C18: m | D18: input | G18: =B18/0.3048 -> 9.1732283
A19: q4 x | B19: 0.479 | C19: m | D19: input | G19: =B19/0.3048 -> 1.5715223
... A23: q4 y | B23: 3.454 | C23: m | D23: input | G23: =B23/0.3048 -> 11.332021
A24: Centroid p̄ x | B24: =AVERAGE($B$8:$B$11) -> 1 | C24: m | D24: mean | E24: 1 | F24: =IF(ABS(B24-E24)<=H24,"OK","CHECK") -> OK | G24: =B24/0.3048 -> 3.2808399 | H24: 1e-09
A25: Centroid p̄ y | B25: =AVERAGE($B$12:$B$15) -> 1 | C25: m | D25: mean | E25: 1 | F25: =IF(ABS(B25-E25)<=H25,"OK","CHECK") -> OK | G25: =B25/0.3048 -> 3.2808399 | H25: 1e-09
A26: Centroid q̄ x | B26: =AVERAGE($B$16:$B$19) -> 1.81125 | C26: m | D26: mean | E26: 1.811 | F26: =IF(ABS(B26-E26)<=H26,"OK","CHECK") -> OK | G26: =B26/0.3048 -> 5.9424213 | H26: 0.0005
A27: Centroid q̄ y | B27: =AVERAGE($B$20:$B$23) -> 1.65825 | C27: m | D27: mean | E27: 1.658 | F27: =IF(ABS(B27-E27)<=H27,"OK","CHECK") -> OK | G27: =B27/0.3048 -> 5.4404528 | H27: 0.0005
A28: W11 = Σ p′x q′x | B28: =SUMPRODUCT($B$8:$B$11-$B$24,$B$16:$B$19-$B$26) -> 4.287 | D28: W = Σ p′ q′ᵀ | E28: 4.287 | F28: =IF(ABS(B28-E28)<=H28,"OK","CHECK") -> OK | H28: 0.002
A29: W12 = Σ p′x q′y | B29: =SUMPRODUCT($B$8:$B$11-$B$24,$B$20:$B$23-$B$27) -> -1.275 | E29: -1.275 | F29: =IF(ABS(B29-E29)<=H29,"OK","CHECK") -> OK | H29: 0.002
A30: W21 = Σ p′y q′x | B30: =SUMPRODUCT($B$12:$B$15-$B$25,$B$16:$B$19-$B$26) -> -3.012 | E30: -3.012 | F30: =IF(ABS(B30-E30)<=H30,"OK","CHECK") -> OK | H30: 0.002
A31: W22 = Σ p′y q′y | B31: =SUMPRODUCT($B$12:$B$15-$B$25,$B$20:$B$23-$B$27) -> 5.561 | E31: 5.562 | F31: =IF(ABS(B31-E31)<=H31,"OK","CHECK") -> OK | H31: 0.002
A32: Σ(p′x q′y − p′y q′x) | B32: =$B$29-$B$30 -> 1.737 | E32: 1.736 | F32: =IF(ABS(B32-E32)<=H32,"OK","CHECK") -> OK | H32: 0.002
A33: Σ(p′x q′x + p′y q′y) | B33: =$B$28+$B$31 -> 9.848 | E33: 9.848 | F33: =IF(ABS(B33-E33)<=H33,"OK","CHECK") -> OK | H33: 0.002
A34: Rotation θ | B34: =DEGREES(ATAN2($B$33,$B$32)) -> 10.003001 | C34: deg | D34: atan2(num, den) [Excel: ATAN2(x, y)] | E34: 10 | F34: =IF(ABS(B34-E34)<=H34,"OK","CHECK") -> OK | H34: 0.01
A35: Translation tx | B35: =$B$26-(COS(RADIANS($B$34))*$B$24-SIN(RADIANS($B$34))*$B$25) -> 1.0001511 | C35: m | D35: t = q̄ − R p̄ | E35: 1 | F35: =IF(ABS(B35-E35)<=H35,"OK","CHECK") -> OK | G35: =B35/0.3048 -> 3.2813357 | H35: 0.001
A36: Translation ty | B36: =$B$27-(SIN(RADIANS($B$34))*$B$24+COS(RADIANS($B$34))*$B$25) -> 0.49975158 | C36: m | E36: 0.5 | F36: =IF(ABS(B36-E36)<=H36,"OK","CHECK") -> OK | G36: =B36/0.3048 -> 1.6396049 | H36: 0.001
A38: Worked example 11.2 — edge or plane?
A39: Given: Two neighbors each side (|S| = 4); center range underlined in the book.
A40: Flat wall range 1 | B40: 10 | C40: m | D40: input | G40: =B40/0.3048 -> 32.808399
A41: Flat wall range 2 | B41: 10.01 | C41: m | D41: input | G41: =B41/0.3048 -> 32.841207
A42: Flat wall range 3 (center) | B42: 10 | C42: m | D42: input | G42: =B42/0.3048 -> 32.808399
A43: Flat wall range 4 | B43: 9.99 | C43: m | D43: input | G43: =B43/0.3048 -> 32.775591
A44: Flat wall range 5 | B44: 10 | C44: m | D44: input | G44: =B44/0.3048 -> 32.808399
A45: Corner range 1 | B45: 10 | C45: m | D45: input | G45: =B45/0.3048 -> 32.808399
A46: Corner range 2 | B46: 10 | C46: m | D46: input | G46: =B46/0.3048 -> 32.808399
...

Sheet M12 Factor Graphs
A1: Module 12 — Factor Graphs and Trajectories: worked examples
A2: Blue = input (edit it) Black = formula Green = linked from another example/sheet Check = formula result vs. the value printed in the seminar book
A4: Step / quantity | B4: Value | C4: Unit | D4: Equation (as in the book) | E4: Book value | F4: Check vs. book | G4: US feet | H4: Tolerance | I4: Notes
A6: Worked example 12.1 — 1-D pose graph with a GPS misclosure
A7: Given: x0 = 0 fixed; odometry 1.0, 1.1, 0.9 m; GPS x3 = 3.2 m; equal weights.
A8: Odometry x1−x0 | B8: 1 | C8: m | D8: input | G8: =B8/0.3048 -> 3.2808399
A9: Odometry x2−x1 | B9: 1.1 | C9: m | D9: input | G9: =B9/0.3048 -> 3.6089239
A10: Odometry x3−x2 | B10: 0.9 | C10: m | D10: input | G10: =B10/0.3048 -> 2.9527559
A11: GPS x3 | B11: 3.2 | C11: m | D11: input | G11: =B11/0.3048 -> 10.498688
A12: AᵀB row 1 | B12: =$B$8-$B$9 -> -0.1 | C12: m | E12: -0.1 | F12: =IF(ABS(B12-E12)<=H12,"OK","CHECK") -> OK | G12: =B12/0.3048 -> -0.32808399 | H12: 1e-09
A13: AᵀB row 2 | B13: =$B$9-$B$10 -> 0.2 | C13: m | E13: 0.2 | F13: =IF(ABS(B13-E13)<=H13,"OK","CHECK") -> OK | G13: =B13/0.3048 -> 0.65616798 | H13: 1e-09
A14: AᵀB row 3 | B14: =$B$10+$B$11 -> 4.1 | C14: m | E14: 4.1 | F14: =IF(ABS(B14-E14)<=H14,"OK","CHECK") -> OK | G14: =B14/0.3048 -> 13.451444 | H14: 1e-09
A15: x1 | B15: =(3*$B$12+2*$B$13+$B$14)/4 -> 1.05 | C15: m | D15: x = (AᵀA)⁻¹Aᵀb, (AᵀA)⁻¹ = ¼[[3,2,1],[2,4,2],[1,2,3]] | E15: 1.05 | F15: =IF(ABS(B15-E15)<=H15,"OK","CHECK") -> OK | G15: =B15/0.3048 -> 3.4448819 | H15: 1e-06
A16: x2 | B16: =(2*$B$12+4*$B$13+2*$B$14)/4 -> 2.2 | C16: m | E16: 2.2 | F16: =IF(ABS(B16-E16)<=H16,"OK","CHECK") -> OK | G16: =B16/0.3048 -> 7.2178478 | H16: 1e-06
A17: x3 | B17: =($B$12+2*$B$13+3*$B$14)/4 -> 3.15 | C17: m | E17: 3.15 | F17: =IF(ABS(B17-E17)<=H17,"OK","CHECK") -> OK | G17: =B17/0.3048 -> 10.334646 | H17: 1e-06
A18: Residual odometry 1 | B18: =$B$15-$B$8 -> 0.05 | C18: m | E18: 0.05 | F18: =IF(ABS(B18-E18)<=H18,"OK","CHECK") -> OK | G18: =B18/0.3048 -> 0.16404199 | H18: 1e-06
A19: Residual odometry 2 | B19: =$B$16-$B$15-$B$9 -> 0.05 | C19: m | E19: 0.05 | F19: =IF(ABS(B19-E19)<=H19,"OK","CHECK") -> OK | G19: =B19/0.3048 -> 0.16404199 | H19: 1e-06
A20: Residual odometry 3 | B20: =$B$17-$B$16-$B$10 -> 0.05 | C20: m | E20: 0.05 | F20: =IF(ABS(B20-E20)<=H20,"OK","CHECK") -> OK | G20: =B20/0.3048 -> 0.16404199 | H20: 1e-06
A21: Residual GPS | B21: =$B$17-$B$11 -> -0.05 | C21: m | E21: -0.05 | F21: =IF(ABS(B21-E21)<=H21,"OK","CHECK") -> OK | G21: =B21/0.3048 -> -0.16404199 | H21: 1e-06
A22: Misclosure | B22: =ABS($B$8+$B$9+$B$10-$B$11) -> 0.2 | C22: m | D22: |Σodometry − GPS| | E22: 0.2 | F22: =IF(ABS(B22-E22)<=H22,"OK","CHECK") -> OK | G22: =B22/0.3048 -> 0.65616798 | H22: 1e-06
A24: Worked example 12.2 — giving a camera image its pose
A25: Given: Poses at 10.00 s and 10.10 s; photo at 10.04 s.
A26: t1 | B26: 10 | C26: s | D26: input
A27: E1 | B27: 100 | C27: m | D27: input | G27: =B27/0.3048 -> 328.08399
A28: N1 | B28: 200 | C28: m | D28: input | G28: =B28/0.3048 -> 656.16798
A29: Heading 1 | B29: 30 | C29: deg | D29: input
A30: t2 | B30: 10.1 | C30: s | D30: input
A31: E2 | B31: 101.5 | C31: m | D31: input | G31: =B31/0.3048 -> 333.00525
A32: N2 | B32: 200.1 | C32: m | D32: input | G32: =B32/0.3048 -> 656.49606
A33: Heading 2 | B33: 31 | C33: deg | D33: input
A34: Exposure time | B34: 10.04 | C34: s | D34: input
A35: Fraction | B35: =($B$34-$B$26)/($B$30-$B$26) -> 0.4 | D35: f = (t − t1)/(t2 − t1) | E35: 0.4 | F35: =IF(ABS(B35-E35)<=H35,"OK","CHECK") -> OK | H35: 1e-06
A36: Image E | B36: =$B$27+$B$35*($B$31-$B$27) -> 100.6 | C36: m | D36: E1 + f(E2 − E1) | E36: 100.6 | F36: =IF(ABS(B36-E36)<=H36,"OK","CHECK") -> OK | G36: =B36/0.3048 -> 330.05249 | H36: 0.005
A37: Image N | B37: =$B$28+$B$35*($B$32-$B$28) -> 200.04 | C37: m | E37: 200.04 | F37: =IF(ABS(B37-E37)<=H37,"OK","CHECK") -> OK | G37: =B37/0.3048 -> 656.29921 | H37: 0.005
A38: Image heading | B38: =$B$29+$B$35*($B$33-$B$29) -> 30.4 | C38: deg | E38: 30.4 | F38: =IF(ABS(B38-E38)<=H38,"OK","CHECK") -> OK | H38: 0.005
A40: Worked example 12.3 — why the camera needs calibration and timing too
A41: Given: Boresight 0.1° at 20 m; timing error 5 ms at 10 m/s.
A42: Boresight error | B42: 0.1 | C42: deg | D42: input
A43: Range | B43: 20 | C43: m | D43: input | G43: =B43/0.3048 -> 65.616798
A44: Timing error | B44: 0.005 | C44: s | D44: input
...

Sheet M13 Accuracy
A1: Module 13 — Control, Checkpoints and ASPRS Accuracy: worked examples
A2: Blue = input (edit it) Black = formula Green = linked from another example/sheet Check = formula result vs. the value printed in the seminar book
A4: Step / quantity | B4: Value | C4: Unit | D4: Equation (as in the book) | E4: Book value | F4: Check vs. book | G4: US feet | H4: Tolerance | I4: Notes
A6: Worked example 13.1 — vertical accuracy from ten checkpoints
A7: Given: Δz (cm) = +2.1, −3.4, +1.2, +4.5, −0.8, +2.7, −1.9, +3.1, +0.4, −2.6; checkpoints RMSE 1.0 cm.
A8: Δz 1 | B8: 2.1 | C8: cm | D8: input | G8: =B8/30.48 -> 0.068897638
A9: Δz 2 | B9: -3.4 | C9: cm | D9: input | G9: =B9/30.48 -> -0.11154856
A10: Δz 3 | B10: 1.2 | C10: cm | D10: input | G10: =B10/30.48 -> 0.039370079
A11: Δz 4 | B11: 4.5 | C11: cm | D11: input | G11: =B11/30.48 -> 0.1476378
A12: Δz 5 | B12: -0.8 | C12: cm | D12: input | G12: =B12/30.48 -> -0.026246719
A13: Δz 6 | B13: 2.7 | C13: cm | D13: input | G13: =B13/30.48 -> 0.088582677
A14: Δz 7 | B14: -1.9 | C14: cm | D14: input | G14: =B14/30.48 -> -0.062335958
A15: Δz 8 | B15: 3.1 | C15: cm | D15: input | G15: =B15/30.48 -> 0.10170604
A16: Δz 9 | B16: 0.4 | C16: cm | D16: input | G16: =B16/30.48 -> 0.01312336
A17: Δz 10 | B17: -2.6 | C17: cm | D17: input | G17: =B17/30.48 -> -0.085301837
A18: Checkpoint survey RMSE | B18: 1 | C18: cm | D18: input | G18: =B18/30.48 -> 0.032808399
A19: Sum | B19: =SUM($B$8:$B$17) -> 5.3 | C19: cm | D19: Σ Δz | E19: 5.3 | F19: =IF(ABS(B19-E19)<=H19,"OK","CHECK") -> OK | G19: =B19/30.48 -> 0.17388451 | H19: 1e-06
A20: Mean (bias) | B20: =AVERAGE($B$8:$B$17) -> 0.53 | C20: cm | D20: Σ Δz / n | E20: 0.53 | F20: =IF(ABS(B20-E20)<=H20,"OK","CHECK") -> OK | G20: =B20/30.48 -> 0.017388451 | H20: 1e-06
A21: Sum of squares | B21: =SUMSQ($B$8:$B$17) -> 65.73 | C21: cm² | D21: Σ Δz² | E21: 65.73 | F21: =IF(ABS(B21-E21)<=H21,"OK","CHECK") -> OK | H21: 1e-06
A22: RMSE_z (data) | B22: =SQRT($B$21/COUNT($B$8:$B$17)) -> 2.5637863 | C22: cm | D22: √(ΣΔz²/n) | E22: 2.56 | F22: =IF(ABS(B22-E22)<=H22,"OK","CHECK") -> OK | G22: =B22/30.48 -> 0.084113723 | H22: 0.005
A23: Standard deviation | B23: =STDEV($B$8:$B$17) -> 2.6440919 | C23: cm | E23: 2.64 | F23: =IF(ABS(B23-E23)<=H23,"OK","CHECK") -> OK | G23: =B23/30.48 -> 0.086748423 | H23: 0.005
A24: RMSE_z incl. checkpoint error | B24: =SQRT($B$22^2+$B$18^2) -> 2.7519084 | C24: cm | D24: √(RMSE² + RMSEck²) | E24: 2.75 | F24: =IF(ABS(B24-E24)<=H24,"OK","CHECK") -> OK | G24: =B24/30.48 -> 0.09028571 | H24: 0.005
A26: Worked example 13.2 — horizontal accuracy
A27: Given: RMSEx = 2.25 cm, RMSEy = 2.16 cm.
A28: RMSE x | B28: 2.25 | C28: cm | D28: input | G28: =B28/30.48 -> 0.073818898
A29: RMSE y | B29: 2.16 | C29: cm | D29: input | G29: =B29/30.48 -> 0.070866142
A30: RMSE_H (radial) | B30: =SQRT($B$28^2+$B$29^2) -> 3.1189902 | C30: cm | D30: √(RMSEx² + RMSEy²) | E30: 3.12 | F30: =IF(ABS(B30-E30)<=H30,"OK","CHECK") -> OK | G30: =B30/30.48 -> 0.10232908 | H30: 0.005

Sheet M14 Error Budgets
A1: Module 14 — Error Propagation and Error Budgets: worked examples
A2: Blue = input (edit it) Black = formula Green = linked from another example/sheet Check = formula result vs. the value printed in the seminar book
A4: Step / quantity | B4: Value | C4: Unit | D4: Equation (as in the book) | E4: Book value | F4: Check vs. book | G4: US feet | H4: Tolerance | I4: Notes
A6: Worked example 14.1 — height of a ground point seen by a scanner
A7: Given: Scanner 2.00 m above a flat road, point 20.00 m away; σρ = 0.35 cm; σV = 0.01°; z = ρ sin V.
A8: Scanner height | B8: 2 | C8: m | D8: input | G8: =B8/0.3048 -> 6.5616798
A9: Horizontal distance | B9: 20 | C9: m | D9: input | G9: =B9/0.3048 -> 65.616798
A10: Range precision σρ | B10: 0.35 | C10: cm | D10: input | G10: =B10/30.48 -> 0.01148294
A11: Vertical angle σV | B11: 0.01 | C11: deg | D11: input
A12: Range ρ | B12: =SQRT($B$9^2+$B$8^2) -> 20.099751 | C12: m | D12: √(d² + h²) | E12: 20.1 | F12: =IF(ABS(B12-E12)<=H12,"OK","CHECK") -> OK | G12: =B12/0.3048 -> 65.944066 | H12: 0.0005
A13: Vertical angle V | B13: =-DEGREES(ATAN($B$8/$B$9)) -> -5.7105931 | C13: deg | D13: −atan(h/d) | E13: -5.711 | F13: =IF(ABS(B13-E13)<=H13,"OK","CHECK") -> OK | H13: 0.0005
A14: sin V = ∂z/∂ρ | B14: =SIN(RADIANS($B$13)) -> -0.099503719 | E14: -0.0995 | F14: =IF(ABS(B14-E14)<=H14,"OK","CHECK") -> OK | H14: 5e-06
A15: cos V | B15: =COS(RADIANS($B$13)) -> 0.99503719 | E15: 0.99504 | F15: =IF(ABS(B15-E15)<=H15,"OK","CHECK") -> OK | H15: 5e-06
A16: ∂z/∂V = ρ cos V | B16: =$B$12*$B$15 -> 20 | C16: m/rad | E16: 20 | F16: =IF(ABS(B16-E16)<=H16,"OK","CHECK") -> OK | H16: 0.0005
A17: σV in radians | B17: =RADIANS($B$11) -> 0.00017453293 | C17: rad | E17: 0.0001745 | F17: =IF(ABS(B17-E17)<=H17,"OK","CHECK") -> OK | H17: 1e-07
A18: Range contribution | B18: =ABS($B$14)*$B$10 -> 0.034826302 | C18: cm | D18: |sin V|·σρ | E18: 0.035 | F18: =IF(ABS(B18-E18)<=H18,"OK","CHECK") -> OK | G18: =B18/30.48 -> 0.0011425952 | H18: 0.0005
A19: Angle contribution | B19: =$B$16*$B$17*100 -> 0.34906585 | C19: cm | D19: ρ cos V·σV | E19: 0.349 | F19: =IF(ABS(B19-E19)<=H19,"OK","CHECK") -> OK | G19: =B19/30.48 -> 0.011452292 | H19: 0.0005
A20: σz | B20: =SQRT($B$18^2+$B$19^2) -> 0.35079886 | C20: cm | D20: √(range² + angle²) | E20: 0.351 | F20: =IF(ABS(B20-E20)<=H20,"OK","CHECK") -> OK | G20: =B20/30.48 -> 0.011509149 | H20: 0.0005
A22: Worked example 14.2 — curb height from one sensor — correlation helps
A23: Given: σ = 0.25 cm random each; common range bias 1.25 cm (r = 1); h = z1 − z2.
A24: Random σ per point | B24: 0.25 | C24: cm | D24: input | G24: =B24/30.48 -> 0.0082020997
A25: Common bias | B25: 1.25 | C25: cm | D25: input | G25: =B25/30.48 -> 0.041010499
A26: Bias correlation | B26: 1 | D26: input
A27: Coefficient a1 | B27: 1 | D27: input
A28: Coefficient a2 | B28: -1 | D28: input
A29: Random variance of h | B29: =$B$27^2*$B$24^2+$B$28^2*$B$24^2 -> 0.125 | C29: cm² | D29: Σ ai² σi² | E29: 0.125 | F29: =IF(ABS(B29-E29)<=H29,"OK","CHECK") -> OK | H29: 1e-06
A30: Bias variance of h | B30: =$B$27^2*$B$25^2+$B$28^2*$B$25^2+2*$B$27*$B$28*$B$26*$B$25*$B$25 -> 0 | C30: cm² | D30: Σ ai²bi² + 2 a1 a2 r b1 b2 | E30: 0 | F30: =IF(ABS(B30-E30)<=H30,"OK","CHECK") -> OK | H30: 1e-09
A31: σh total | B31: =SQRT($B$29+$B$30) -> 0.35355339 | C31: cm | E31: 0.35 | F31: =IF(ABS(B31-E31)<=H31,"OK","CHECK") -> OK | G31: =B31/30.48 -> 0.011599521 | H31: 0.005
A32: Absolute height σ (each point) | B32: =SQRT($B$24^2+$B$25^2) -> 1.2747549 | C32: cm | D32: √(σ² + b²) | E32: 1.3 | F32: =IF(ABS(B32-E32)<=H32,"OK","CHECK") -> OK | G32: =B32/30.48 -> 0.041822667 | H32: 0.05
A34: Worked example 14.3 — the error ellipsoid of one laser point
A35: Given: ρ = 30.00 m, H = 30°, V = −3.823°; σρ = 10 mm; σH = σV = 0.01°.
A36: Range ρ | B36: 30 | C36: m | D36: input | G36: =B36/0.3048 -> 98.425197
A37: H | B37: 30 | C37: deg | D37: input
A38: V | B38: -3.823 | C38: deg | D38: input
A39: σρ | B39: 10 | C39: mm | D39: input | G39: =B39/304.8 -> 0.032808399
A40: σH | B40: 0.01 | C40: deg | D40: input
A41: σV | B41: 0.01 | C41: deg | D41: input
A42: Point x | B42: =$B$36*COS(RADIANS($B$38))*COS(RADIANS($B$37)) -> 25.922949 | C42: m | D42: ρ cos V cos H | E42: 25.923 | F42: =IF(ABS(B42-E42)<=H42,"OK","CHECK") -> OK | G42: =B42/0.3048 -> 85.049046 | H42: 0.0005
A43: Point y | B43: =$B$36*COS(RADIANS($B$38))*SIN(RADIANS($B$37)) -> 14.966622 | C43: m | D43: ρ cos V sin H | E43: 14.967 | F43: =IF(ABS(B43-E43)<=H43,"OK","CHECK") -> OK | G43: =B43/0.3048 -> 49.10309 | H43: 0.0005
A44: Point z | B44: =$B$36*SIN(RADIANS($B$38)) -> -2.0002331 | C44: m | D44: ρ sin V | E44: -2 | F44: =IF(ABS(B44-E44)<=H44,"OK","CHECK") -> OK | G44: =B44/0.3048 -> -6.5624447 | H44: 0.0005
...

Sheet M15 Ouster OS0
A1: Module 15 — Ouster OS0 Case Study: worked examples
A2: Blue = input (edit it) Black = formula Green = linked from another example/sheet Check = formula result vs. the value printed in the seminar book
A4: Step / quantity | B4: Value | C4: Unit | D4: Equation (as in the book) | E4: Book value | F4: Check vs. book | G4: US feet | H4: Tolerance | I4: Notes
A6: Worked example 15.1 — spacing on a building face
A7: Given: OS0-128, 1024 @ 10 Hz; wall 20 m away.
A8: Columns | B8: 1024 | D8: input
A9: Channels | B9: 128 | D9: input
A10: Vertical FOV | B10: 90 | C10: deg | D10: input
A11: Range | B11: 20 | C11: m | D11: input | G11: =B11/0.3048 -> 65.616798
A12: Horizontal step | B12: =360/$B$8 -> 0.3515625 | C12: deg | D12: 360°/Ncol | E12: 0.3516 | F12: =IF(ABS(B12-E12)<=H12,"OK","CHECK") -> OK | H12: 5e-05
A13: Horizontal step (rad) | B13: =RADIANS($B$12) -> 0.0061359232 | C13: rad | E13: 0.006136 | F13: =IF(ABS(B13-E13)<=H13,"OK","CHECK") -> OK | H13: 5e-07
A14: Horizontal spacing | B14: =$B$11*$B$13 -> 0.12271846 | C14: m | D14: ρΔθ | E14: 0.123 | F14: =IF(ABS(B14-E14)<=H14,"OK","CHECK") -> OK | G14: =B14/0.3048 -> 0.40261963 | H14: 0.0005
A15: Vertical step | B15: =$B$10/($B$9-1) -> 0.70866142 | C15: deg | D15: FOV/(Nch − 1) | E15: 0.7087 | F15: =IF(ABS(B15-E15)<=H15,"OK","CHECK") -> OK | H15: 5e-05
A16: Vertical step (rad) | B16: =RADIANS($B$15) -> 0.012368475 | C16: rad | E16: 0.01237 | F16: =IF(ABS(B16-E16)<=H16,"OK","CHECK") -> OK | H16: 5e-06
A17: Vertical spacing | B17: =$B$11*$B$16 -> 0.2473695 | C17: m | E17: 0.247 | F17: =IF(ABS(B17-E17)<=H17,"OK","CHECK") -> OK | G17: =B17/0.3048 -> 0.81157973 | H17: 0.0005
A19: Worked example 15.2 — does 4096 mode make the map sharper?
A20: Given: Exit 5 mm, divergence 0.35°, range 20 m.
A21: Exit diameter | B21: 0.005 | C21: m | D21: input | G21: =B21/0.3048 -> 0.016404199
A22: Divergence | B22: 0.35 | C22: deg | D22: input
